Workbook
Name FID_1: [1]AGR_Fuels!$A$2

Sheet EnergyBalance
P1: Default Units | Q1: Currency | R1: Activity | S1: Emissions
D2: COA | E2: GAS | F2: OIL | G2: NUC | H2: RNW | I2: SLU | J2: HET | K2: ELC | Q2: M€2005 | R2: PJ | S2: kt | W2: COA | X2: GAS | Y2: OIL | Z2: NUC | AA2: RNW | AB2: SLU | AC2: HET | AD2: ELC
D3: Solid Fuels | E3: Natural Gas | F3: Crude Oil | G3: Nuclear Energy | H3: Renewable Energies | I3: Industrial Wastes | J3: Derived Heat | K3: Electricity | L3: Total | U3: Break-out by Region 1 | W3: Solid Fuels | X3: Natural Gas | Y3: Crude oil | Z3: Nuclear Energy | AA3: Renewable Energies | AB3: Industrial Wastes | AC3: Derived Heat | AD3: Electricity
C4: PRIMARY | V4: PRIMARY
B5: MIN | C5: Domestic Supply | D5: 8098.358 | E5: 7899.497 | F5: 5378.512 | G5: 10775.149 | H5: 5026.6 | I5: 0 | J5: 0 | K5: 0 | L5: =SUM(D5:K5) -> 37178.116 | U5: MIN | V5: Domestic Supply | W5: 1 | X5: 0 | Y5: 0.3 | Z5: 0 | AA5: 1 | AB5: 0.5 | AC5: 0.5 | AD5: 0.5
B6: IMP | C6: Imports | D6: 6462.671 | E6: 13291.729 | F6: 39959.98 | G6: 0 | H6: 113.019 | I6: 0.007 | J6: 0.153 | K6: 1167.52 | L6: =SUM(D6:K6) -> 60995.079 | U6: IMP | V6: Imports | W6: 1 | X6: 0 | Y6: 0.3 | Z6: 0 | AA6: 1 | AB6: 0.5 | AC6: 0.5 | AD6: 0.5
B7: EXP | C7: Exports | D7: -1147.069 | E7: -2516.331 | F7: -14830.662 | G7: 0 | H7: -72.404 | I7: 0 | J7: -0.129 | K7: -1126.804 | L7: =SUM(D7:K7) -> -19693.399 | U7: EXP | V7: Exports | W7: 1 | X7: 0 | Y7: 0.3 | Z7: 0 | AA7: 1 | AB7: 0.5 | AC7: 0.5 | AD7: 0.5
B8: TPS | C8: Total Primary Supply | D8: =SUM(D5:D7) -> 13413.96 | E8: =SUM(E5:E7) -> 18674.895 | F8: =SUM(F5:F7) -> 30507.83 | G8: =SUM(G5:G7) -> 10775.149 | H8: =SUM(H5:H7) -> 5067.215 | I8: =SUM(I5:I7) -> 0.007 | J8: =SUM(J5:J7) -> 0.024 | K8: =SUM(K5:K7) -> 40.716 | L8: =SUM(L5:L7) -> 78479.796
C9: CONVERSION | V9: CONVERSION
B10: ESC | C10: Energy Sector Consumption | D10: -57.638 | E10: -792.98 | F10: -1848.605 | G10: 0 | H10: -4.283 | I10: -1.52 | J10: 0 | K10: 0 | L10: =SUM(D10:K10) -> -2705.026 | U10: ESC | V10: Energy Sector Consumption | W10: 1 | X10: 0 | Y10: 0.3 | Z10: 0 | AA10: 1 | AB10: 0.5 | AC10: 0.5
B11: ELC | C11: Electricity Plants | D11: -9598.12 | E11: -5635.544 | F11: -1224.609 | G11: -10775.149 | H11: -1255.692 | I11: -32.949 | J11: 1737.559 | K11: 11581.04 | L11: =SUM(D11:K11) -> -15203.464 | U11: ELC | V11: Electricity Plants | W11: 1 | X11: 0 | Y11: 0.3 | Z11: 0 | AA11: 1 | AB11: 0.5 | AC11: 0.5 | AD11: 0.5
B12: HPL | C12: Heat Plants | D12: -161.396 | E12: -301.301 | F12: -49.649 | G12: 0 | H12: -140.207 | I12: -1.569 | J12: 658.743 | K12: 0 | L12: =SUM(D12:K12) -> 4.621 | U12: HPL | V12: Heat Plants | W12: 1 | X12: 0 | Y12: 0.3 | Z12: 0 | AA12: 1 | AB12: 0.5 | AC12: 0.5
B13: REF | C13: Petroleum Refineries | F13: -31736.461 | L13: =SUM(D13:K13) -> -31736.461 | U13: REF | V13: Petroleum Refineries | W13: 1 | X13: 0 | Y13: 0.3 | Z13: 0 | AA13: 1 | AB13: 0.5 | AC13: 0.5
C14: Total Conversion | D14: =SUM(D10:D13) -> -9817.154 | E14: =SUM(E10:E13) -> -6729.825 | F14: =SUM(F10:F13) -> -34859.324 | G14: =SUM(G10:G13) -> -10775.149 | H14: =SUM(H10:H13) -> -1400.182 | I14: =SUM(I10:I13) -> -36.038 | J14: =SUM(J10:J13) -> 2396.302 | K14: =SUM(K10:K13) -> 11581.04 | L14: =SUM(L10:L13) -> -49640.33 | Z14: 0
C15: FINAL | V15: FINAL | Z15: 0
B16: RSD | C16: Residential | D16: 356.555 | E16: 5159.793 | F16: 2289.293 | G16: 0 | H16: 1293.927 | I16: 0 | J16: 865.485 | K16: 2871.742 | L16: =SUM(D16:K16) -> 12836.795 | U16: RSD | V16: Residential | W16: 1 | X16: 0 | Y16: 0.3 | Z16: 0 | AA16: 1 | AB16: 0.5 | AC16: 0.5 | AD16: 0.5
B17: COM | C17: Commercial | D17: 56.925 | E17: 1751.73 | F17: 854.81 | G17: 0 | H17: 67.406 | I17: 1.217 | J17: 254.646 | K17: 2527.391 | L17: =SUM(D17:K17) -> 5514.125 | U17: COM | V17: Commercial | W17: 1 | X17: 0 | Y17: 0.3 | Z17: 0 | AA17: 1 | AB17: 0.5 | AC17: 0.5 | AD17: 0.5
B18: IND | C18: Industry | D18: 1896.986 | E18: 4437.161 | F18: 2016.111 | G18: 0 | H18: 721.671 | I18: 117.192 | J18: 633.583 | K18: 4088.444 | L18: =SUM(D18:K18) -> 13911.148 | U18: IND | V18: Industry | W18: 1 | X18: 0 | Y18: 0.3 | Z18: 0 | AA18: 1 | AB18: 0.5 | AC18: 0.5 | AD18: 0.5
B19: AGR | C19: Agriculture | D19: 44.1 | E19: 201.206 | F19: 797.372 | G19: 0 | H19: 63.086 | I19: 0.001 | J19: 15.574 | K19: 19.386 | L19: =SUM(D19:K19) -> 1140.725 | U19: AGR | V19: Agriculture | W19: 1 | X19: 0 | Y19: 0.3 | Z19: 0 | AA19: 1 | AB19: 0.5 | AC19: 0.5 | AD19: 0.5
B20: TRA | C20: Transport | D20: 0.556 | E20: 21.249 | F20: 14851.249 | G20: 0 | H20: 130.685 | I20: 0 | J20: 0 | K20: 265.972 | L20: =SUM(D20:K20) -> 15269.711 | U20: TRA | V20: Transport | W20: 1 | X20: 0 | Y20: 0.3 | Z20: 0 | AA20: 1 | AB20: 0.5 | AC20: 0.5 | AD20: 0.5
B21: OTH | C21: Other | D21: =IF((SUM(D16:D20,D22:D23)-SUM(D10:D12))>D8,0,(D8-SUM(D16:D20,D22:D23)+SUM(D10:D12))) -> 1189.231 | E21: =IF((SUM(E16:E20,E22:E23)-SUM(E10:E12))>E8,0,(E8-SUM(E16:E20,E22:E23)+SUM(E10:E12))) -> 0 | F21: 392.532 | G21: =IF((SUM(G16:G20,G22:G23)-SUM(G10:G12))>G8,0,(G8-SUM(G16:G20,G22:G23)+SUM(G10:G12))) -> 0 | H21: =IF((SUM(H16:H20,H22:H23)-SUM(H10:H12))>H8,0,(H8-SUM(H16:H20,H22:H23)+SUM(H10:H12))) -> 1390.258 | I21: =IF((SUM(I16:I20,I22:I23)-SUM(I10:I12))>I8,0,(I8-SUM(I16:I20,I22:I23)+SUM(I10:I12))) -> 0 | J21: =IF((SUM(J16:J20,J22:J23)-SUM(J10:J12))>J8,0,(J8-SUM(J16:J20,J22:J23)+SUM(J10:J12))) -> 627.038 | K21: 650 | L21: =SUM(D21:K21) -> 4249.059 | U21: OTH | V21: Other | W21: 1 | X21: 0 | Y21: 0.3 | Z21: 0 | AA21: 1 | AB21: 0.5 | AC21: 0.5 | AD21: 0.5
B22: NEN | C22: Non Energy | D22: 52.453 | E22: 633.823 | F22: 4072.508 | H22: 0 | I22: 0 | J22: 0 | K22: 0 | L22: =SUM(D22:K22) -> 4758.784 | U22: NEN | V22: Non Energy | W22: 1 | X22: 0 | Y22: 0.3 | Z22: 0 | AA22: 1 | AB22: 0.5 | AC22: 0.5 | AD22: 0.5
B23: BNK | C23: Bunkers | D23: 0 | E23: 0 | F23: 2111.092 | H23: 0 | I23: 0 | J23: 0 | K23: 0 | L23: =SUM(D23:K23) -> 2111.092 | U23: BNK | V23: Bunkers | W23: 1 | X23: 0 | Y23: 0.3 | Z23: 0 | AA23: 1 | AB23: 0.5 | AC23: 0.5 | AD23: 0.5
B24: TFC | C24: Total Final Consumption | D24: =SUM(D16:D23) -> 3596.806 | E24: =SUM(E16:E23) -> 12204.962 | F24: =SUM(F16:F23) -> 27384.967 | G24: =SUM(G16:G23) -> 0 | H24: =SUM(H16:H23) -> 3667.033 | I24: =SUM(I16:I23) -> 118.41 | J24: =SUM(J16:J23) -> 2396.326 | K24: =SUM(K16:K23) -> 10422.935 | L24: =SUM(L16:L23) -> 59791.439 | U24: TFC | W24: 1 | AD24: 0.5
C27: Data used in the template to buld the model
D36: COA | E36: GAS | F36: OIL
C37: Domestic Supply Curve Share - Step 1 | D37: 0.75 | E37: 0.5 | F37: 0.8
C38: Domestic Supply Curve Share - Step 2 | D38: 0.25 | E38: 0.5 | F38: 0.2
B41: Sector | C41: Break-out by end-use | D41: Solid Fuels | E41: Natural Gas | F41: Crude oil | G41: Nuclear Energy | H41: Renewable Energies | I41: Industrial Wastes | J41: Derived Heat | K41: Electricity
B42: RSD | C42: SH | N42: Space Heating
B43: RSD | C43: AP | N43: Appliancens
B44: RSD | C44: OT | E44: 1 | N44: Other
B46: COM | C46: D1 | N46: Demand 1
B47: COM | C47: D6 | N47: Demand 6
B49: TRA | C49: D1 | F49: 1 | N49: Demand 1
C52: CO2 | D52: Nox | E52: VOC
B53: Emission by sector | C53: Carbon dioxide | D53: NOX | E53: VOC
B54: RSD | C54: 1
B55: TRA | C55: 1
B56: OTH | C56: 1
...

Sheet EB1
Q1: Default Units | R1: Currency | S1: Activity | T1: Emissions
D2: COA | E2: GAS | F2: OIL | G2: NUC | H2: RNW | I2: SLU | J2: HET | K2: ELC | R2: M€ | S2: PJ | T2: kt
C3: REG1 | D3: Solid Fuels | E3: Natural Gas | F3: Crude Oil | G3: Nuclear Energy | H3: Renewable Energies | I3: Industrial Wastes | J3: Derived Heat | K3: Electricity | L3: Total
C4: PRIMARY
B5: MIN | C5: Domestic Supply | D5: =EnergyBalance!D5*EnergyBalance!W5 -> 8098.358 | E5: =EnergyBalance!E5*EnergyBalance!X5 -> 0 | F5: =EnergyBalance!F5*EnergyBalance!Y5 -> 1613.5536 | G5: =EnergyBalance!G5*EnergyBalance!Z5 -> 0 | H5: =EnergyBalance!H5*EnergyBalance!AA5 -> 5026.6 | I5: =EnergyBalance!I5*EnergyBalance!AB5 -> 0 | J5: =EnergyBalance!J5*EnergyBalance!AC5 -> 0 | K5: =EnergyBalance!K5*EnergyBalance!AD5 -> 0 | L5: =SUM(D5:K5) -> 14738.512
B6: IMP | C6: Imports | D6: =EnergyBalance!D6*EnergyBalance!W6 -> 6462.671 | E6: =EnergyBalance!E6*EnergyBalance!X6 -> 0 | F6: =EnergyBalance!F6*EnergyBalance!Y6 -> 11987.994 | G6: =EnergyBalance!G6*EnergyBalance!Z6 -> 0 | H6: =EnergyBalance!H6*EnergyBalance!AA6 -> 113.019 | I6: =EnergyBalance!I6*EnergyBalance!AB6 -> 0.0035 | J6: =EnergyBalance!J6*EnergyBalance!AC6 -> 0.0765 | K6: =EnergyBalance!K6*EnergyBalance!AD6 -> 583.76 | L6: =SUM(D6:K6) -> 19147.524
B7: EXP | C7: Exports | D7: =EnergyBalance!D7*EnergyBalance!W7 -> -1147.069 | E7: =EnergyBalance!E7*EnergyBalance!X7 -> 0 | F7: =EnergyBalance!F7*EnergyBalance!Y7 -> -4449.1986 | G7: =EnergyBalance!G7*EnergyBalance!Z7 -> 0 | H7: =EnergyBalance!H7*EnergyBalance!AA7 -> -72.404 | I7: =EnergyBalance!I7*EnergyBalance!AB7 -> 0 | J7: =EnergyBalance!J7*EnergyBalance!AC7 -> -0.0645 | K7: =EnergyBalance!K7*EnergyBalance!AD7 -> -563.402 | L7: =SUM(D7:K7) -> -6232.1381
B8: TPS | C8: Total Primary Supply | D8: =SUM(D5:D7) -> 13413.96 | E8: =SUM(E5:E7) -> 0 | F8: =SUM(F5:F7) -> 9152.349 | G8: =SUM(G5:G7) -> 0 | H8: =SUM(H5:H7) -> 5067.215 | I8: =SUM(I5:I7) -> 0.0035 | J8: =SUM(J5:J7) -> 0.012 | K8: =SUM(K5:K7) -> 20.358 | L8: =SUM(D8:K8) -> 27653.897
C9: CONVERSION
B10: ESC | C10: Energy Sector Consumption | D10: =EnergyBalance!D10*EnergyBalance!W10 -> -57.638 | E10: =EnergyBalance!E10*EnergyBalance!X10 -> 0 | F10: =EnergyBalance!F10*EnergyBalance!Y10 -> -554.5815 | G10: =EnergyBalance!G10*EnergyBalance!Z10 -> 0 | H10: =EnergyBalance!H10*EnergyBalance!AA10 -> -4.283 | I10: =EnergyBalance!I10*EnergyBalance!AB10 -> -0.76 | J10: =EnergyBalance!J10*EnergyBalance!AC10 -> 0 | K10: =EnergyBalance!K10*EnergyBalance!AD10 -> 0 | L10: =SUM(D10:K10) -> -617.2625
B11: ELC | C11: Electricity Plants | D11: =EnergyBalance!D11*EnergyBalance!W11 -> -9598.12 | E11: =EnergyBalance!E11*EnergyBalance!X11 -> 0 | F11: =EnergyBalance!F11*EnergyBalance!Y11 -> -367.3827 | G11: =EnergyBalance!G11*EnergyBalance!Z11 -> 0 | H11: =EnergyBalance!H11*EnergyBalance!AA11 -> -1255.692 | I11: =EnergyBalance!I11*EnergyBalance!AB11 -> -16.4745 | J11: =EnergyBalance!J11*EnergyBalance!AC11 -> 868.7795 | K11: =EnergyBalance!K11*EnergyBalance!AD11 -> 5790.52 | L11: =SUM(D11:K11) -> -4578.3697
B12: HPL | C12: Heat Plants | D12: =EnergyBalance!D12*EnergyBalance!W12 -> -161.396 | E12: =EnergyBalance!E12*EnergyBalance!X12 -> 0 | F12: =EnergyBalance!F12*EnergyBalance!Y12 -> -14.8947 | G12: =EnergyBalance!G12*EnergyBalance!Z12 -> 0 | H12: =EnergyBalance!H12*EnergyBalance!AA12 -> -140.207 | I12: =EnergyBalance!I12*EnergyBalance!AB12 -> -0.7845 | J12: =EnergyBalance!J12*EnergyBalance!AC12 -> 329.3715 | K12: =EnergyBalance!K12*EnergyBalance!AD12 -> 0 | L12: =SUM(D12:K12) -> 12.0893
B13: REF | C13: Petroleum Refineries | D13: =EnergyBalance!D13*EnergyBalance!W13 -> 0 | E13: =EnergyBalance!E13*EnergyBalance!X13 -> 0 | F13: =EnergyBalance!F13*EnergyBalance!Y13 -> -9520.9383 | G13: =EnergyBalance!G13*EnergyBalance!Z13 -> 0 | H13: =EnergyBalance!H13*EnergyBalance!AA13 -> 0 | I13: =EnergyBalance!I13*EnergyBalance!AB13 -> 0 | J13: =EnergyBalance!J13*EnergyBalance!AC13 -> 0 | K13: =EnergyBalance!K13*EnergyBalance!AD13 -> 0 | L13: =SUM(D13:K13) -> -9520.9383
C14: Total Conversion | D14: =SUM(D10:D13) -> -9817.154 | E14: =SUM(E10:E13) -> 0 | F14: =SUM(F10:F13) -> -10457.797 | G14: =SUM(G10:G13) -> 0 | H14: =SUM(H10:H13) -> -1400.182 | I14: =SUM(I10:I13) -> -18.019 | J14: =SUM(J10:J13) -> 1198.151 | K14: =SUM(K10:K13) -> 5790.52 | L14: =SUM(D14:K14) -> -14704.481
C15: FINAL
B16: RSD | C16: Residential | D16: =EnergyBalance!D16*EnergyBalance!W16 -> 356.555 | E16: =EnergyBalance!E16*EnergyBalance!X16 -> 0 | F16: =EnergyBalance!F16*EnergyBalance!Y16 -> 686.7879 | G16: =EnergyBalance!G16*EnergyBalance!Z16 -> 0 | H16: =EnergyBalance!H16*EnergyBalance!AA16 -> 1293.927 | I16: =EnergyBalance!I16*EnergyBalance!AB16 -> 0 | J16: =EnergyBalance!J16*EnergyBalance!AC16 -> 432.7425 | K16: =EnergyBalance!K16*EnergyBalance!AD16 -> 1435.871 | L16: =SUM(D16:K16) -> 4205.8834
B17: COM | C17: Commercial | D17: =EnergyBalance!D17*EnergyBalance!W17 -> 56.925 | E17: =EnergyBalance!E17*EnergyBalance!X17 -> 0 | F17: =EnergyBalance!F17*EnergyBalance!Y17 -> 256.443 | G17: =EnergyBalance!G17*EnergyBalance!Z17 -> 0 | H17: =EnergyBalance!H17*EnergyBalance!AA17 -> 67.406 | I17: =EnergyBalance!I17*EnergyBalance!AB17 -> 0.6085 | J17: =EnergyBalance!J17*EnergyBalance!AC17 -> 127.323 | K17: =EnergyBalance!K17*EnergyBalance!AD17 -> 1263.6955 | L17: =SUM(D17:K17) -> 1772.401
B18: IND | C18: Industry | D18: =EnergyBalance!D18*EnergyBalance!W18 -> 1896.986 | E18: =EnergyBalance!E18*EnergyBalance!X18 -> 0 | F18: =EnergyBalance!F18*EnergyBalance!Y18 -> 604.8333 | G18: =EnergyBalance!G18*EnergyBalance!Z18 -> 0 | H18: =EnergyBalance!H18*EnergyBalance!AA18 -> 721.671 | I18: =EnergyBalance!I18*EnergyBalance!AB18 -> 58.596 | J18: =EnergyBalance!J18*EnergyBalance!AC18 -> 316.7915 | K18: =EnergyBalance!K18*EnergyBalance!AD18 -> 2044.222 | L18: =SUM(D18:K18) -> 5643.0998
B19: AGR | C19: Agriculture | D19: =EnergyBalance!D19*EnergyBalance!W19 -> 44.1 | E19: =EnergyBalance!E19*EnergyBalance!X19 -> 0 | F19: =EnergyBalance!F19*EnergyBalance!Y19 -> 239.2116 | G19: =EnergyBalance!G19*EnergyBalance!Z19 -> 0 | H19: =EnergyBalance!H19*EnergyBalance!AA19 -> 63.086 | I19: =EnergyBalance!I19*EnergyBalance!AB19 -> 0.0005 | J19: =EnergyBalance!J19*EnergyBalance!AC19 -> 7.787 | K19: =EnergyBalance!K19*EnergyBalance!AD19 -> 9.693 | L19: =SUM(D19:K19) -> 363.8781
B20: TRA | C20: Transport | D20: =EnergyBalance!D20*EnergyBalance!W20 -> 0.556 | E20: =EnergyBalance!E20*EnergyBalance!X20 -> 0 | F20: =EnergyBalance!F20*EnergyBalance!Y20 -> 4455.3747 | G20: =EnergyBalance!G20*EnergyBalance!Z20 -> 0 | H20: =EnergyBalance!H20*EnergyBalance!AA20 -> 130.685 | I20: =EnergyBalance!I20*EnergyBalance!AB20 -> 0 | J20: =EnergyBalance!J20*EnergyBalance!AC20 -> 0 | K20: =EnergyBalance!K20*EnergyBalance!AD20 -> 132.986 | L20: =SUM(D20:K20) -> 4719.6017
B21: OTH | C21: Other | D21: =EnergyBalance!D21*EnergyBalance!W21 -> 1189.231 | E21: =EnergyBalance!E21*EnergyBalance!X21 -> 0 | F21: =EnergyBalance!F21*EnergyBalance!Y21 -> 117.7596 | G21: =EnergyBalance!G21*EnergyBalance!Z21 -> 0 | H21: =EnergyBalance!H21*EnergyBalance!AA21 -> 1390.258 | I21: =EnergyBalance!I21*EnergyBalance!AB21 -> 0 | J21: =EnergyBalance!J21*EnergyBalance!AC21 -> 313.519 | K21: =EnergyBalance!K21*EnergyBalance!AD21 -> 325 | L21: =SUM(D21:K21) -> 3335.7676
B22: NEN | C22: Non Energy | D22: =EnergyBalance!D22*EnergyBalance!W22 -> 52.453 | E22: =EnergyBalance!E22*EnergyBalance!X22 -> 0 | F22: =EnergyBalance!F22*EnergyBalance!Y22 -> 1221.7524 | G22: =EnergyBalance!G22*EnergyBalance!Z22 -> 0 | H22: =EnergyBalance!H22*EnergyBalance!AA22 -> 0 | I22: =EnergyBalance!I22*EnergyBalance!AB22 -> 0 | J22: =EnergyBalance!J22*EnergyBalance!AC22 -> 0 | K22: =EnergyBalance!K22*EnergyBalance!AD22 -> 0 | L22: =SUM(D22:K22) -> 1274.2054
B23: BNK | C23: Bunkers | D23: =EnergyBalance!D23*EnergyBalance!W23 -> 0 | E23: =EnergyBalance!E23*EnergyBalance!X23 -> 0 | F23: =EnergyBalance!F23*EnergyBalance!Y23 -> 633.3276 | G23: =EnergyBalance!G23*EnergyBalance!Z23 -> 0 | H23: =EnergyBalance!H23*EnergyBalance!AA23 -> 0 | I23: =EnergyBalance!I23*EnergyBalance!AB23 -> 0 | J23: =EnergyBalance!J23*EnergyBalance!AC23 -> 0 | K23: =EnergyBalance!K23*EnergyBalance!AD23 -> 0 | L23: =SUM(D23:K23) -> 633.3276
B24: TFC | C24: Total Final Consumption | D24: =SUM(D16:D23) -> 3596.806 | E24: =SUM(E16:E23) -> 0 | F24: =SUM(F16:F23) -> 8215.4901 | G24: =SUM(G16:G23) -> 0 | H24: =SUM(H16:H23) -> 3667.033 | I24: =SUM(I16:I23) -> 59.205 | J24: =SUM(J16:J23) -> 1198.163 | K24: =SUM(K16:K23) -> 5211.4675 | L24: =SUM(D24:K24) -> 21948.165
C27: Data used in the template to buld the model
D36: COA | E36: GAS | F36: OIL
C37: Domestic Supply Curve Share - Step 1 | D37: 0.75 | E37: 0.5 | F37: 0.8
C38: Domestic Supply Curve Share - Step 2 | D38: 0.25 | E38: 0.5 | F38: 0.2
B41: Sector | C41: Break-out by end-use | D41: Solid Fuels | E41: Natural Gas | F41: Crude oil | G41: Nuclear Energy | H41: Renewable Energies | I41: Industrial Wastes | J41: Derived Heat | K41: Electricity
B42: RSD | C42: SH | N42: Space Heating
B43: RSD | C43: AP | N43: Appliancens
B44: RSD | C44: OT | E44: 1 | N44: Other
B46: COM | C46: D1 | N46: Demand 1
B47: COM | C47: D6 | N47: Demand 6
B49: TRA | C49: D1 | F49: 1 | N49: Demand 1
C52: CO2 | D52: Nox | E52: VOC
B53: Emission by sector | C53: Carbon dioxide | D53: NOX | E53: VOC
B54: RSD | C54: 1
B55: TRA | C55: 1
B56: OTH | C56: 1
...

Sheet EB2
Q1: Default Units | R1: Currency | S1: Activity | T1: Emissions
D2: COA | E2: GAS | F2: OIL | G2: NUC | H2: RNW | I2: SLU | J2: HET | K2: ELC | R2: M€ | S2: PJ | T2: kt
C3: REG2 | D3: Solid Fuels | E3: Natural Gas | F3: Crude Oil | G3: Nuclear Energy | H3: Renewable Energies | I3: Industrial Wastes | J3: Derived Heat | K3: Electricity | L3: Total
C4: PRIMARY
B5: MIN | C5: Domestic Supply | D5: =EnergyBalance!D5-'EB1'!D5 -> 0 | E5: =EnergyBalance!E5-'EB1'!E5 -> 7899.497 | F5: =EnergyBalance!F5-'EB1'!F5 -> 3764.9584 | G5: =EnergyBalance!G5-'EB1'!G5 -> 10775.149 | H5: =EnergyBalance!H5-'EB1'!H5 -> 0 | I5: =EnergyBalance!I5-'EB1'!I5 -> 0 | J5: =EnergyBalance!J5-'EB1'!J5 -> 0 | K5: =EnergyBalance!K5-'EB1'!K5 -> 0 | L5: =SUM(D5:K5) -> 22439.604
B6: IMP | C6: Imports | D6: =EnergyBalance!D6-'EB1'!D6 -> 0 | E6: =EnergyBalance!E6-'EB1'!E6 -> 13291.729 | F6: =EnergyBalance!F6-'EB1'!F6 -> 27971.986 | G6: =EnergyBalance!G6-'EB1'!G6 -> 0 | H6: =EnergyBalance!H6-'EB1'!H6 -> 0 | I6: =EnergyBalance!I6-'EB1'!I6 -> 0.0035 | J6: =EnergyBalance!J6-'EB1'!J6 -> 0.0765 | K6: =EnergyBalance!K6-'EB1'!K6 -> 583.76 | L6: =SUM(D6:K6) -> 41847.555
B7: EXP | C7: Exports | D7: =EnergyBalance!D7-'EB1'!D7 -> 0 | E7: =EnergyBalance!E7-'EB1'!E7 -> -2516.331 | F7: =EnergyBalance!F7-'EB1'!F7 -> -10381.463 | G7: =EnergyBalance!G7-'EB1'!G7 -> 0 | H7: =EnergyBalance!H7-'EB1'!H7 -> 0 | I7: =EnergyBalance!I7-'EB1'!I7 -> 0 | J7: =EnergyBalance!J7-'EB1'!J7 -> -0.0645 | K7: =EnergyBalance!K7-'EB1'!K7 -> -563.402 | L7: =SUM(D7:K7) -> -13461.261
B8: TPS | C8: Total Primary Supply | D8: =SUM(D5:D7) -> 0 | E8: =SUM(E5:E7) -> 18674.895 | F8: =SUM(F5:F7) -> 21355.481 | G8: =SUM(G5:G7) -> 10775.149 | H8: =SUM(H5:H7) -> 0 | I8: =SUM(I5:I7) -> 0.0035 | J8: =SUM(J5:J7) -> 0.012 | K8: =SUM(K5:K7) -> 20.358 | L8: =SUM(L5:L7) -> 50825.899
C9: CONVERSION
B10: ESC | C10: Energy Sector Consumption | D10: =EnergyBalance!D10-'EB1'!D10 -> 0 | E10: =EnergyBalance!E10-'EB1'!E10 -> -792.98 | F10: =EnergyBalance!F10-'EB1'!F10 -> -1294.0235 | G10: =EnergyBalance!G10-'EB1'!G10 -> 0 | H10: =EnergyBalance!H10-'EB1'!H10 -> 0 | I10: =EnergyBalance!I10-'EB1'!I10 -> -0.76 | J10: =EnergyBalance!J10-'EB1'!J10 -> 0 | K10: =EnergyBalance!K10-'EB1'!K10 -> 0 | L10: =SUM(D10:K10) -> -2087.7635
B11: ELC | C11: Electricity Plants | D11: =EnergyBalance!D11-'EB1'!D11 -> 0 | E11: =EnergyBalance!E11-'EB1'!E11 -> -5635.544 | F11: =EnergyBalance!F11-'EB1'!F11 -> -857.2263 | G11: =EnergyBalance!G11-'EB1'!G11 -> -10775.149 | H11: =EnergyBalance!H11-'EB1'!H11 -> 0 | I11: =EnergyBalance!I11-'EB1'!I11 -> -16.4745 | J11: =EnergyBalance!J11-'EB1'!J11 -> 868.7795 | K11: =EnergyBalance!K11-'EB1'!K11 -> 5790.52 | L11: =SUM(D11:K11) -> -10625.094
B12: HPL | C12: Heat Plants | D12: =EnergyBalance!D12-'EB1'!D12 -> 0 | E12: =EnergyBalance!E12-'EB1'!E12 -> -301.301 | F12: =EnergyBalance!F12-'EB1'!F12 -> -34.7543 | G12: =EnergyBalance!G12-'EB1'!G12 -> 0 | H12: =EnergyBalance!H12-'EB1'!H12 -> 0 | I12: =EnergyBalance!I12-'EB1'!I12 -> -0.7845 | J12: =EnergyBalance!J12-'EB1'!J12 -> 329.3715 | K12: =EnergyBalance!K12-'EB1'!K12 -> 0 | L12: =SUM(D12:K12) -> -7.4683
B13: REF | C13: Petroleum Refineries | D13: =EnergyBalance!D13-'EB1'!D13 -> 0 | E13: =EnergyBalance!E13-'EB1'!E13 -> 0 | F13: =EnergyBalance!F13-'EB1'!F13 -> -22215.523 | G13: =EnergyBalance!G13-'EB1'!G13 -> 0 | H13: =EnergyBalance!H13-'EB1'!H13 -> 0 | I13: =EnergyBalance!I13-'EB1'!I13 -> 0 | J13: =EnergyBalance!J13-'EB1'!J13 -> 0 | K13: =EnergyBalance!K13-'EB1'!K13 -> 0 | L13: =SUM(D13:K13) -> -22215.523
C14: Total Conversion | D14: =SUM(D10:D13) -> 0 | E14: =SUM(E10:E13) -> -6729.825 | F14: =SUM(F10:F13) -> -24401.527 | G14: =SUM(G10:G13) -> -10775.149 | H14: =SUM(H10:H13) -> 0 | I14: =SUM(I10:I13) -> -18.019 | J14: =SUM(J10:J13) -> 1198.151 | K14: =SUM(K10:K13) -> 5790.52 | L14: =SUM(L10:L13) -> -34935.849
C15: FINAL
B16: RSD | C16: Residential | D16: =EnergyBalance!D16-'EB1'!D16 -> 0 | E16: =EnergyBalance!E16-'EB1'!E16 -> 5159.793 | F16: =EnergyBalance!F16-'EB1'!F16 -> 1602.5051 | G16: =EnergyBalance!G16-'EB1'!G16 -> 0 | H16: =EnergyBalance!H16-'EB1'!H16 -> 0 | I16: =EnergyBalance!I16-'EB1'!I16 -> 0 | J16: =EnergyBalance!J16-'EB1'!J16 -> 432.7425 | K16: =EnergyBalance!K16-'EB1'!K16 -> 1435.871 | L16: =SUM(D16:K16) -> 8630.9116
B17: COM | C17: Commercial | D17: =EnergyBalance!D17-'EB1'!D17 -> 0 | E17: =EnergyBalance!E17-'EB1'!E17 -> 1751.73 | F17: =EnergyBalance!F17-'EB1'!F17 -> 598.367 | G17: =EnergyBalance!G17-'EB1'!G17 -> 0 | H17: =EnergyBalance!H17-'EB1'!H17 -> 0 | I17: =EnergyBalance!I17-'EB1'!I17 -> 0.6085 | J17: =EnergyBalance!J17-'EB1'!J17 -> 127.323 | K17: =EnergyBalance!K17-'EB1'!K17 -> 1263.6955 | L17: =SUM(D17:K17) -> 3741.724
B18: IND | C18: Industry | D18: =EnergyBalance!D18-'EB1'!D18 -> 0 | E18: =EnergyBalance!E18-'EB1'!E18 -> 4437.161 | F18: =EnergyBalance!F18-'EB1'!F18 -> 1411.2777 | G18: =EnergyBalance!G18-'EB1'!G18 -> 0 | H18: =EnergyBalance!H18-'EB1'!H18 -> 0 | I18: =EnergyBalance!I18-'EB1'!I18 -> 58.596 | J18: =EnergyBalance!J18-'EB1'!J18 -> 316.7915 | K18: =EnergyBalance!K18-'EB1'!K18 -> 2044.222 | L18: =SUM(D18:K18) -> 8268.0482
B19: AGR | C19: Agriculture | D19: =EnergyBalance!D19-'EB1'!D19 -> 0 | E19: =EnergyBalance!E19-'EB1'!E19 -> 201.206 | F19: =EnergyBalance!F19-'EB1'!F19 -> 558.1604 | G19: =EnergyBalance!G19-'EB1'!G19 -> 0 | H19: =EnergyBalance!H19-'EB1'!H19 -> 0 | I19: =EnergyBalance!I19-'EB1'!I19 -> 0.0005 | J19: =EnergyBalance!J19-'EB1'!J19 -> 7.787 | K19: =EnergyBalance!K19-'EB1'!K19 -> 9.693 | L19: =SUM(D19:K19) -> 776.8469
B20: TRA | C20: Transport | D20: =EnergyBalance!D20-'EB1'!D20 -> 0 | E20: =EnergyBalance!E20-'EB1'!E20 -> 21.249 | F20: =EnergyBalance!F20-'EB1'!F20 -> 10395.874 | G20: =EnergyBalance!G20-'EB1'!G20 -> 0 | H20: =EnergyBalance!H20-'EB1'!H20 -> 0 | I20: =EnergyBalance!I20-'EB1'!I20 -> 0 | J20: =EnergyBalance!J20-'EB1'!J20 -> 0 | K20: =EnergyBalance!K20-'EB1'!K20 -> 132.986 | L20: =SUM(D20:K20) -> 10550.109
B21: OTH | C21: Other | D21: =EnergyBalance!D21-'EB1'!D21 -> 0 | E21: =EnergyBalance!E21-'EB1'!E21 -> 0 | F21: =EnergyBalance!F21-'EB1'!F21 -> 274.7724 | G21: =EnergyBalance!G21-'EB1'!G21 -> 0 | H21: =EnergyBalance!H21-'EB1'!H21 -> 0 | I21: =EnergyBalance!I21-'EB1'!I21 -> 0 | J21: =EnergyBalance!J21-'EB1'!J21 -> 313.519 | K21: =EnergyBalance!K21-'EB1'!K21 -> 325 | L21: =SUM(D21:K21) -> 913.2914
B22: NEN | C22: Non Energy | D22: =EnergyBalance!D22-'EB1'!D22 -> 0 | E22: =EnergyBalance!E22-'EB1'!E22 -> 633.823 | F22: =EnergyBalance!F22-'EB1'!F22 -> 2850.7556 | G22: =EnergyBalance!G22-'EB1'!G22 -> 0 | H22: =EnergyBalance!H22-'EB1'!H22 -> 0 | I22: =EnergyBalance!I22-'EB1'!I22 -> 0 | J22: =EnergyBalance!J22-'EB1'!J22 -> 0 | K22: =EnergyBalance!K22-'EB1'!K22 -> 0 | L22: =SUM(D22:K22) -> 3484.5786
B23: BNK | C23: Bunkers | D23: =EnergyBalance!D23-'EB1'!D23 -> 0 | E23: =EnergyBalance!E23-'EB1'!E23 -> 0 | F23: =EnergyBalance!F23-'EB1'!F23 -> 1477.7644 | G23: =EnergyBalance!G23-'EB1'!G23 -> 0 | H23: =EnergyBalance!H23-'EB1'!H23 -> 0 | I23: =EnergyBalance!I23-'EB1'!I23 -> 0 | J23: =EnergyBalance!J23-'EB1'!J23 -> 0 | K23: =EnergyBalance!K23-'EB1'!K23 -> 0 | L23: =SUM(D23:K23) -> 1477.7644
B24: TFC | C24: Total Final Consumption | D24: =SUM(D16:D23) -> 0 | E24: =SUM(E16:E23) -> 12204.962 | F24: =SUM(F16:F23) -> 19169.477 | G24: =SUM(G16:G23) -> 0 | H24: =SUM(H16:H23) -> 0 | I24: =SUM(I16:I23) -> 59.205 | J24: =SUM(J16:J23) -> 1198.163 | K24: =SUM(K16:K23) -> 5211.4675 | L24: =SUM(L16:L23) -> 37843.274
C27: Data used in the template to buld the model
D36: COA | E36: GAS | F36: OIL
C37: Domestic Supply Curve Share - Step 1 | D37: 0.75 | E37: 0.5 | F37: 0.8
C38: Domestic Supply Curve Share - Step 2 | D38: 0.25 | E38: 0.5 | F38: 0.2
B41: Sector | C41: Break-out by end-use | D41: Solid Fuels | E41: Natural Gas | F41: Crude oil | G41: Nuclear Energy | H41: Renewable Energies | I41: Industrial Wastes | J41: Derived Heat | K41: Electricity
B42: RSD | C42: SH | N42: Space Heating
B43: RSD | C43: AP | N43: Appliancens
B44: RSD | C44: OT | E44: 1 | N44: Other
B46: COM | C46: D1 | N46: Demand 1
B47: COM | C47: D6 | N47: Demand 6
B49: TRA | C49: D1 | F49: 1 | N49: Demand 1
C52: CO2 | D52: Nox | E52: VOC
B53: Emission by sector | C53: Carbon dioxide | D53: NOX | E53: VOC
B54: RSD | C54: 1
B55: TRA | C55: 1
B56: OTH | C56: 1
...

Sheet RES&OBJ
B2: _SysCost result table
B4: Objective Function
B6: Run name: DemoS_004
B18: Reference Energy System
D20: Primary Supply (Mining, Import/Export) | N20: Conversion (Power Sector) | X20: Demand Sectors

Sheet Pri_COA
B1: Sector Name | C1: Commodity | D1: Description | E1: Default Unit | F1: Currency Unit
C2: =EnergyBalance!D2 -> COA | D2: =EnergyBalance!D3 -> Solid Fuels | E2: =EnergyBalance!R2 -> PJ | F2: =EnergyBalance!Q2 -> M€2005 | J2: ~FI_Comm
J3: Csets | K3: Region | L3: CommName | M3: CommDesc | N3: Unit | O3: LimType | P3: CTSLvl | Q3: PeakTS | R3: Ctype
J4: *Commodity Set Membership | K4: Region Name | L4: Commodity Name | M4: Commodity Description | N4: Unit | O4: Sense of the Balance EQN. | P4: Timeslice Level | Q4: Peak Monitoring | R4: Electricity Indicator
J5: NRG | L5: =C2 -> COA | M5: =D2 -> Solid Fuels | N5: =$E$2 -> PJ
E7: ~FI_T | J7: ~FI_Process
B8: Region | C8: TechName | D8: Comm-IN | E8: Comm-OUT | F8: CUM | G8: COST | H8: ACT_BND | J8: Sets | K8: Region | L8: TechName | M8: TechDesc | N8: Tact | O8: Tcap | P8: Tslvl | Q8: PrimaryCG | R8: Vintage
B9: Region Name | C9: *Technology Name | D9: Input Commodity | E9: Output Commodity | F9: Reserves Cumulative Value | G9: Cost | H9: Annual Production Bound | J9: *Process Set Membership | K9: Region Name | L9: Technology Name | M9: Technology Description | N9: Activity Unit | O9: Capacity Unit | P9: TimeSlice level of Process Activity | Q9: Primary Commodity Group | R9: Vintage Tracking
C10: *Units | F10: =$E$2 -> PJ | G10: =$F$2&"/"&$E$2 -> M€2005/PJ | H10: =$E$2 -> PJ | J10: *
B11: REG1 | C11: =L11 -> MINCOA1 | E11: =$L$5 -> COA | F11: 80000 | G11: 2 | H11: ='EB1'!$D$5*'EB1'!D37 -> 6073.7685 | J11: =EnergyBalance!$B$5 -> MIN | K11: REG1 | L11: =$J$11&$C$2&1 -> MINCOA1 | M11: ="Domestic Supply of "&$D$2& " Step "&RIGHT(L11,1) -> Domestic Supply of Solid Fuels Step 1 | N11: =$E$2 -> PJ
B12: REG1 | C12: =L12 -> MINCOA2 | E12: =$L$5 -> COA | F12: 160000 | G12: 2.5 | H12: ='EB1'!$D$5*'EB1'!D38 -> 2024.5895 | K12: REG1 | L12: =$J$11&$C$2&2 -> MINCOA2 | M12: ="Domestic Supply of "&$D$2& " Step "&RIGHT(L12,1) -> Domestic Supply of Solid Fuels Step 2 | N12: =$E$2 -> PJ
B13: REG1 | C13: =L13 -> MINCOA3 | E13: =$L$5 -> COA | F13: 320000 | G13: 3 | K13: REG1 | L13: =$J$11&$C$2&3 -> MINCOA3 | M13: ="Domestic Supply of "&$D$2& " Step "&RIGHT(L13,1) -> Domestic Supply of Solid Fuels Step 3 | N13: =$E$2 -> PJ
B14: REG1 | C14: =L14 -> IMPCOA1 | E14: =$L$5 -> COA | G14: 2.75 | J14: =EnergyBalance!$B$6 -> IMP | K14: REG1 | L14: =$J$14&$C$2&1 -> IMPCOA1 | M14: ="Import of "&$D$2& " Step "&RIGHT(L14,1) -> Import of Solid Fuels Step 1 | N14: =$E$2 -> PJ
B15: REG1 | C15: =L15 -> EXPCOA1 | D15: =$L$5 -> COA | G15: 2.75 | H15: =-EnergyBalance!D7 -> 1147.069 | J15: =EnergyBalance!B7 -> EXP | K15: REG1 | L15: =$J$15&$C$2&1 -> EXPCOA1 | M15: ="Export of "&$D$2& " Step "&RIGHT(L15,1) -> Export of Solid Fuels Step 1 | N15: =$E$2 -> PJ
C22: User inputs
C23: Linked to the Energy Balance

Sheet Pri_GAS
B1: Sector Name | C1: Commodity | D1: Description | E1: Default Unit | F1: Currency Unit
C2: =EnergyBalance!E2 -> GAS | D2: =EnergyBalance!E3 -> Natural Gas | E2: =EnergyBalance!R2 -> PJ | F2: =EnergyBalance!Q2 -> M€2005 | J2: ~FI_Comm
J3: Csets | K3: Region | L3: CommName | M3: CommDesc | N3: Unit | O3: LimType | P3: CTSLvl | Q3: PeakTS | R3: Ctype
J4: *Commodity Set Membership | K4: Region Name | L4: Commodity Name | M4: Commodity Description | N4: Unit | O4: Sense of the Balance EQN. | P4: Timeslice Level | Q4: Peak Monitoring | R4: Electricity Indicator
J5: NRG | L5: =C2 -> GAS | M5: =D2 -> Natural Gas | N5: =$E$2 -> PJ
E7: ~FI_T | J7: ~FI_Process
B8: Region | C8: TechName | D8: Comm-IN | E8: Comm-OUT | F8: CUM | G8: COST | H8: ACT_BND | J8: Sets | K8: Region | L8: TechName | M8: TechDesc | N8: Tact | O8: Tcap | P8: Tslvl | Q8: PrimaryCG | R8: Vintage
B9: Region Name | C9: *Technology Name | D9: Input Commodity | E9: Output Commodity | F9: Reserves Cumulative Value | G9: Cost | H9: Annual Production Bound | J9: *Process Set Membership | K9: Region Name | L9: Technology Name | M9: Technology Description | N9: Activity Unit | O9: Capacity Unit | P9: TimeSlice level of Process Activity | Q9: Primary Commodity Group | R9: Vintage Tracking
C10: *Units | F10: =$E$2 -> PJ | G10: =$F$2&"/"&$E$2 -> M€2005/PJ | H10: =$E$2 -> PJ | J10: *
B11: REG2 | C11: =L11 -> MINGAS1 | E11: =$L$5 -> GAS | F11: 15000 | G11: 3.6 | H11: ='EB2'!$E$5*'EB2'!E37 -> 3949.7485 | J11: =EnergyBalance!$B$5 -> MIN | K11: REG2 | L11: =$J$11&$C$2&1 -> MINGAS1 | M11: ="Domestic Supply of "&$D$2& " Step "&RIGHT(L11,1) -> Domestic Supply of Natural Gas Step 1 | N11: =$E$2 -> PJ
B12: REG2 | C12: =L12 -> MINGAS2 | E12: =$L$5 -> GAS | F12: 20000 | G12: 4.14 | H12: ='EB2'!$E$5*'EB2'!E38 -> 3949.7485 | K12: REG2 | L12: =$J$11&$C$2&2 -> MINGAS2 | M12: ="Domestic Supply of "&$D$2& " Step "&RIGHT(L12,1) -> Domestic Supply of Natural Gas Step 2 | N12: =$E$2 -> PJ
B13: REG2 | C13: =L13 -> MINGAS3 | E13: =$L$5 -> GAS | F13: 30000 | G13: 5.4 | K13: REG2 | L13: =$J$11&$C$2&3 -> MINGAS3 | M13: ="Domestic Supply of "&$D$2& " Step "&RIGHT(L13,1) -> Domestic Supply of Natural Gas Step 3 | N13: =$E$2 -> PJ
B14: REG2 | C14: =L14 -> IMPGAS1 | E14: =$L$5 -> GAS | G14: 4.5 | J14: =EnergyBalance!$B$6 -> IMP | K14: REG2 | L14: =$J$14&$C$2&1 -> IMPGAS1 | M14: ="Import of "&$D$2& " Step "&RIGHT(L14,1) -> Import of Natural Gas Step 1 | N14: =$E$2 -> PJ
C15: =L15 -> EXPGAS1 | D15: =$L$5 -> GAS | G15: 4.5 | J15: =EnergyBalance!B7 -> EXP | L15: =$J$15&$C$2&1 -> EXPGAS1 | M15: ="Export of "&$D$2& " Step "&RIGHT(L15,1) -> Export of Natural Gas Step 1 | N15: =$E$2 -> PJ
B16: REG1 | H16: =-EnergyBalance!E7 -> 2516.331
B17: REG2 | H17: =-'EB2'!E7 -> 2516.331
C22: User inputs
C23: Linked to the Energy Balance

Sheet Pri_OIL
B1: Sector Name | C1: Commodity | D1: Description | E1: Default Unit | F1: Currency Unit
C2: =EnergyBalance!F2 -> OIL | D2: =EnergyBalance!F3 -> Crude Oil | E2: =EnergyBalance!R2 -> PJ | F2: =EnergyBalance!Q2 -> M€2005 | J2: ~FI_Comm
J3: Csets | K3: Region | L3: CommName | M3: CommDesc | N3: Unit | O3: LimType | P3: CTSLvl | Q3: PeakTS | R3: Ctype
J4: *Commodity Set Membership | K4: Region Name | L4: Commodity Name | M4: Commodity Description | N4: Unit | O4: Sense of the Balance EQN. | P4: Timeslice Level | Q4: Peak Monitoring | R4: Electricity Indicator
J5: NRG | L5: =C2 -> OIL | M5: =D2 -> Crude Oil | N5: =$E$2 -> PJ
E7: ~FI_T | J7: ~FI_Process
B8: Region | C8: TechName | D8: Comm-IN | E8: Comm-OUT | F8: CUM | G8: COST | H8: ACT_BND | J8: Sets | K8: Region | L8: TechName | M8: TechDesc | N8: Tact | O8: Tcap | P8: Tslvl | Q8: PrimaryCG | R8: Vintage
B9: Region Name | C9: *Technology Name | D9: Input Commodity | E9: Output Commodity | F9: Reserves Cumulative Value | G9: Cost | H9: Annual Production Bound | J9: *Process Set Membership | K9: Region Name | L9: Technology Name | M9: Technology Description | N9: Activity Unit | O9: Capacity Unit | P9: TimeSlice level of Process Activity | Q9: Primary Commodity Group | R9: Vintage Tracking
C10: *Units | F10: =$E$2 -> PJ | G10: =$F$2&"/"&$E$2 -> M€2005/PJ | H10: =$E$2 -> PJ | J10: *
C11: =L11 -> MINOIL1 | E11: =$L$5 -> OIL | G11: 6.4 | J11: =EnergyBalance!$B$5 -> MIN | L11: =$J$11&$C$2&1 -> MINOIL1 | M11: ="Domestic Supply of "&$D$2& " Step "&RIGHT(L11,1) -> Domestic Supply of Crude Oil Step 1 | N11: =$E$2 -> PJ
B12: REG1 | F12: =24000*EnergyBalance!$Y$5 -> 7200 | H12: ='EB1'!$F$5*'EB1'!F37 -> 1290.8429 | L12: =$J$11&$C$2&2 -> MINOIL2 | M12: ="Domestic Supply of "&$D$2& " Step "&RIGHT(L12,1) -> Domestic Supply of Crude Oil Step 2 | N12: =$E$2 -> PJ
B13: REG2 | F13: =24000*(1-EnergyBalance!$Y$5) -> 16800 | H13: ='EB2'!$F$5*'EB2'!F37 -> 3011.9667 | L13: =$J$11&$C$2&3 -> MINOIL3 | M13: ="Domestic Supply of "&$D$2& " Step "&RIGHT(L13,1) -> Domestic Supply of Crude Oil Step 3 | N13: =$E$2 -> PJ
C14: =L12 -> MINOIL2 | E14: =$L$5 -> OIL | G14: 7.36 | J14: =EnergyBalance!$B$6 -> IMP | L14: =$J$14&$C$2&1 -> IMPOIL1 | M14: ="Import of "&$D$2& " Step "&RIGHT(L14,1) -> Import of Crude Oil Step 1 | N14: =$E$2 -> PJ
B15: REG1 | F15: =6000*EnergyBalance!$Y$5 -> 1800 | H15: ='EB1'!$F$5*'EB1'!F38 -> 322.71072 | J15: =EnergyBalance!B7 -> EXP | L15: =$J$15&$C$2&1 -> EXPOIL1 | M15: ="Export of "&$D$2& " Step "&RIGHT(L15,1) -> Export of Crude Oil Step 1 | N15: =$E$2 -> PJ
B16: REG2 | F16: =6000*(1-EnergyBalance!$Y$5) -> 4200 | H16: ='EB2'!$F$5*'EB2'!F38 -> 752.99168
C17: =L13 -> MINOIL3 | E17: =$L$5 -> OIL | G17: 9.6
B18: REG1 | F18: =40000*(EnergyBalance!$Y$5) -> 12000
B19: REG2 | F19: =40000*(1-EnergyBalance!$Y$5) -> 28000
C20: =L14 -> IMPOIL1 | E20: =$L$5 -> OIL | G20: 8
C21: =L15 -> EXPOIL1 | D21: =$L$5 -> OIL | G21: 8
B22: REG1 | H22: =-'EB1'!F7 -> 4449.1986
B23: REG2 | H23: =-'EB2'!F7 -> 10381.463
C27: User inputs
C28: Linked to the Energy Balance

Sheet Pri_RNW
B1: Sector Name | C1: Commodity | D1: Description | E1: Default Unit | F1: Currency Unit
C2: =EnergyBalance!H2 -> RNW | D2: =EnergyBalance!H3 -> Renewable Energies | E2: =EnergyBalance!R2 -> PJ | F2: =EnergyBalance!Q2 -> M€2005 | I2: ~FI_Comm
I3: Csets | J3: Region | K3: CommName | L3: CommDesc | M3: Unit | N3: LimType | O3: CTSLvl | P3: PeakTS | Q3: Ctype
I4: *Commodity Set Membership | J4: Region Name | K4: Commodity Name | L4: Commodity Description | M4: Unit | N4: Sense of the Balance EQN. | O4: Timeslice Level | P4: Peak Monitoring | Q4: Electricity Indicator
I5: NRG | K5: =C2 -> RNW | L5: =D2 -> Renewable Energies | M5: =$E$2 -> PJ
D7: ~FI_T | I7: ~FI_Process
B8: TechName | C8: Comm-IN | D8: Comm-OUT | E8: CUM | F8: COST | G8: ACT_BND | I8: Sets | J8: Region | K8: TechName | L8: TechDesc | M8: Tact | N8: Tcap | O8: Tslvl | P8: PrimaryCG | Q8: Vintage
B9: *Technology Name | C9: Input Commodity | D9: Output Commodity | E9: Reserves Cumulative Value | F9: Cost | G9: Annual Production Bound | I9: *Process Set Membership | J9: Region Name | K9: Technology Name | L9: Technology Description | M9: Activity Unit | N9: Capacity Unit | O9: TimeSlice level of Process Activity | P9: Primary Commodity Group | Q9: Vintage Tracking
B10: *Units | E10: =$E$2 -> PJ | F10: =$F$2&"/"&$E$2 -> M€2005/PJ | G10: =$E$2 -> PJ | I10: *
B11: =K11 -> MINRNW1 | D11: =$K$5 -> RNW | I11: =EnergyBalance!$B$5 -> MIN | K11: =$I$11&$C$2&1 -> MINRNW1 | L11: ="Domestic Supply of "&$D$2& " Step "&RIGHT(K11,1) -> Domestic Supply of Renewable Energies Step 1 | M11: =$E$2 -> PJ
C23: User inputs
C24: Linked to the Energy Balance

Sheet Pri_NUC
B1: Sector Name | C1: Commodity | D1: Description | E1: Default Unit | F1: Currency Unit
C2: =EnergyBalance!G2 -> NUC | D2: =EnergyBalance!G3 -> Nuclear Energy | E2: =EnergyBalance!R2 -> PJ | F2: =EnergyBalance!Q2 -> M€2005 | I2: ~FI_Comm
I3: Csets | J3: Region | K3: CommName | L3: CommDesc | M3: Unit | N3: LimType | O3: CTSLvl | P3: PeakTS | Q3: Ctype
I4: *Commodity Set Membership | J4: Region Name | K4: Commodity Name | L4: Commodity Description | M4: Unit | N4: Sense of the Balance EQN. | O4: Timeslice Level | P4: Peak Monitoring | Q4: Electricity Indicator
I5: NRG | K5: =C2 -> NUC | L5: =D2 -> Nuclear Energy | M5: =$E$2 -> PJ
D7: ~FI_T | I7: ~FI_Process
B8: TechName | C8: Comm-IN | D8: Comm-OUT | E8: CUM | F8: COST | G8: ACT_BND | I8: Sets | J8: Region | K8: TechName | L8: TechDesc | M8: Tact | N8: Tcap | O8: Tslvl | P8: PrimaryCG | Q8: Vintage
B9: *Technology Name | C9: Input Commodity | D9: Output Commodity | E9: Reserves Cumulative Value | F9: Cost | G9: Annual Production Bound | I9: *Process Set Membership | J9: Region Name | K9: Technology Name | L9: Technology Description | M9: Activity Unit | N9: Capacity Unit | O9: TimeSlice level of Process Activity | P9: Primary Commodity Group | Q9: Vintage Tracking
B10: *Units | E10: =$E$2 -> PJ | F10: =$F$2&"/"&$E$2 -> M€2005/PJ | G10: =$E$2 -> PJ | I10: *
B11: =K11 -> MINNUC1 | D11: =$K$5 -> NUC | I11: =EnergyBalance!$B$5 -> MIN | K11: =$I$11&$C$2&1 -> MINNUC1 | L11: ="Domestic Supply of "&$D$2& " Step "&RIGHT(K11,1) -> Domestic Supply of Nuclear Energy Step 1 | M11: =$E$2 -> PJ
C23: User inputs
C24: Linked to the Energy Balance

Sheet Sector_Fuels
B1: Sector Name | C1: Commodity | D1: Description | E1: Deafult unit | F1: Currency | G1: Existing
D2: Sector Fuel | E2: =EnergyBalance!R2 -> PJ | F2: =EnergyBalance!Q2 -> M€2005 | G2: E | J2: ~FI_Comm
J3: Csets | K3: Region | L3: CommName | M3: CommDesc | N3: Unit | O3: LimType | P3: CTSLvl | Q3: PeakTS | R3: Ctype
J4: *Commodity Set Membership | K4: Region Name | L4: Commodity Name | M4: Commodity Description | N4: Unit | O4: Sense of the Balance EQN. | P4: Timeslice Level | Q4: Peak Monitoring | R4: Electricity Indicator
J5: NRG | L5: =EnergyBalance!$B$16&EnergyBalance!$E$2 -> RSDGAS | M5: =EnergyBalance!$C$16&" "&EnergyBalance!$E$3 -> Residential Natural Gas | N5: =$E$2 -> PJ
L6: =EnergyBalance!$B$20&EnergyBalance!$F$2 -> TRAOIL | M6: =EnergyBalance!$C$20&" "&EnergyBalance!$F$3 -> Transport Crude Oil | N6: =$E$2 -> PJ
L7: =Con_ELC!$B$2&EnergyBalance!$D$2 -> ELCCOA | M7: =Con_ELC!$C$2&" "&EnergyBalance!$D$3 -> Electricity Plants Solid Fuels | N7: =$E$2 -> PJ
L8: =Con_ELC!$B$2&EnergyBalance!$E$2 -> ELCGAS | M8: =Con_ELC!$C$2&" "&EnergyBalance!$E$3 -> Electricity Plants Natural Gas | N8: =$E$2 -> PJ
L9: =Con_ELC!$B$2&EnergyBalance!$F$2 -> ELCOIL | M9: =Con_ELC!$C$2&" "&EnergyBalance!$F$3 -> Electricity Plants Crude Oil | N9: =$E$2 -> PJ
L10: =Con_ELC!$B$2&EnergyBalance!$H$2 -> ELCRNW | M10: =Con_ELC!$C$2&" "&EnergyBalance!$H$3 -> Electricity Plants Renewable Energies | N10: =$E$2 -> PJ
L11: =Con_ELC!$B$2&EnergyBalance!$G$2 -> ELCNUC | M11: =Con_ELC!$C$2&" "&EnergyBalance!$G$3 -> Electricity Plants Nuclear Energy | N11: =$E$2 -> PJ
D13: ~FI_T | J13: ~FI_Process
B14: TechName | C14: Comm-IN | D14: Comm-OUT | E14: STOCK~REG1 | F14: STOCK~REG2 | G14: EFF | H14: LIFE | J14: Sets | K14: Region | L14: TechName | M14: TechDesc | N14: Tact | O14: Tcap | P14: Tslvl | Q14: PrimaryCG | R14: Vintage
B15: *Technology Name | C15: Input Commodity | D15: Output Commodity | E15: Existing Installed Capacity | F15: Existing Installed Capacity | G15: Efficiency | H15: Lifetime | J15: *Process Set Membership | K15: Region Name | L15: Technology Name | M15: Technology Description | N15: Activity Unit | O15: Capacity Unit | P15: TimeSlice level of Process Activity | Q15: Primary Commodity Group | R15: Vintage Tracking
B16: *Units | E16: =E2&"a" -> PJa | F16: =E2&"a" -> PJa | H16: Years | J16: *
B17: =L17 -> FTE-RSDGAS | C17: =RIGHT(D17,3) -> GAS | D17: =$L$5 -> RSDGAS | G17: 1 | H17: 30 | J17: PRE | L17: ="FT"&$G$2&"-"&L5 -> FTE-RSDGAS | M17: =$D$2&" "&$G$1&" "&EnergyBalance!$C$16& " Sector- "&EnergyBalance!$E$3 -> Sector Fuel Existing Residential Sector- Natural Gas | N17: =$E$2 -> PJ | O17: =$E$2&"a" -> PJa
B18: =L18 -> FTE-TRAOIL | C18: =RIGHT(D18,3) -> OIL | D18: =$L$6 -> TRAOIL | G18: 1 | H18: 30 | L18: ="FT"&$G$2&"-"&L6 -> FTE-TRAOIL | M18: =$D$2&" "&$G$1&" "&EnergyBalance!$C$20& " Sector- "&EnergyBalance!$F$3 -> Sector Fuel Existing Transport Sector- Crude Oil | N18: =$E$2 -> PJ | O18: =$E$2&"a" -> PJa
B19: =L19 -> FTE-ELCCOA | C19: =RIGHT(D19,3) -> COA | D19: =L7 -> ELCCOA | G19: 1 | H19: 30 | L19: ="FT"&$G$2&"-"&L7 -> FTE-ELCCOA | M19: =$D$2&" Technology"&" "&$G$1&" "&M7 -> Sector Fuel Technology Existing Electricity Plants Solid Fuels | N19: =$E$2 -> PJ | O19: =$E$2&"a" -> PJa
B20: =L20 -> FTE-ELCGAS | C20: =RIGHT(D20,3) -> GAS | D20: =L8 -> ELCGAS | G20: 1 | H20: 30 | L20: ="FT"&$G$2&"-"&L8 -> FTE-ELCGAS | M20: =$D$2&" Technology"&" "&$G$1&" "&M8 -> Sector Fuel Technology Existing Electricity Plants Natural Gas | N20: =$E$2 -> PJ | O20: =$E$2&"a" -> PJa
B21: =L21 -> FTE-ELCOIL | C21: =RIGHT(D21,3) -> OIL | D21: =L9 -> ELCOIL | G21: 1 | H21: 30 | L21: ="FT"&$G$2&"-"&L9 -> FTE-ELCOIL | M21: =$D$2&" Technology"&" "&$G$1&" "&M9 -> Sector Fuel Technology Existing Electricity Plants Crude Oil | N21: =$E$2 -> PJ | O21: =$E$2&"a" -> PJa
B22: =L22 -> FTE-ELCRNW | C22: =RIGHT(D22,3) -> RNW | D22: =L10 -> ELCRNW | G22: 1 | H22: 30 | L22: ="FT"&$G$2&"-"&L10 -> FTE-ELCRNW | M22: =$D$2&" Technology"&" "&$G$1&" "&M10 -> Sector Fuel Technology Existing Electricity Plants Renewable Energies | N22: =$E$2 -> PJ | O22: =$E$2&"a" -> PJa
B23: =L23 -> FTE-ELCNUC | C23: =RIGHT(D23,3) -> NUC | D23: =L11 -> ELCNUC | G23: 1 | H23: 30 | L23: ="FT"&$G$2&"-"&L11 -> FTE-ELCNUC | M23: =$D$2&" Technology"&" "&$G$1&" "&M11 -> Sector Fuel Technology Existing Electricity Plants Nuclear Energy | N23: =$E$2 -> PJ | O23: =$E$2&"a" -> PJa
C32: User inputs
C33: Linked to the Energy Balance

Sheet Con_ELC
B1: Sector Name | C1: Description | D1: Type | E1: Activity Unit | F1: Capacity unit | G1: Currency Unit | I1: Existing | J1: New
B2: =EnergyBalance!B11 -> ELC | C2: =EnergyBalance!C11 -> Electricity Plants | D2: Power Plants | E2: =EnergyBalance!R2 -> PJ | F2: GW | G2: =EnergyBalance!Q2 -> M€2005 | I2: E | J2: N | W2: ~FI_Comm
W3: Csets | X3: Region | Y3: CommName | Z3: CommDesc | AA3: Unit | AB3: LimType | AC3: CTSLvl | AD3: PeakTS | AE3: Ctype
B4: Power Plant Type | C4: Thermal | D4: CHP | E4: Renewable | F4: Nuclear | W4: *Commodity Set Membership | X4: Region Name | Y4: Commodity Name | Z4: Commodity Description | AA4: Unit | AB4: Sense of the Balance EQN. | AC4: Timeslice Level | AD4: Peak Monitoring | AE4: Electricity Indicator
B5: Code | C5: T | D5: C | E5: R | F5: N | W5: NRG | Y5: =EnergyBalance!$K$2 -> ELC | Z5: =EnergyBalance!$K$3 -> Electricity | AA5: =$E$2 -> PJ | AC5: DAYNITE | AE5: ELC
W6: ENV | Y6: =$B$2&EnergyBalance!$C$52 -> ELCCO2 | Z6: =$C$2&" "&EnergyBalance!$C$53 -> Electricity Plants Carbon dioxide | AA6: =EnergyBalance!$S$2 -> kt
D8: ~FI_T | W8: ~FI_Process
B9: TechName | C9: Comm-IN | D9: Comm-OUT | E9: STOCK~REG1 | F9: STOCK~REG2 | G9: STOCK~REG1~2030 | H9: STOCK~REG2~2030 | I9: EFF | J9: AFA | K9: INVCOST | L9: FIXOM | M9: VAROM | N9: LIFE | O9: START | P9: ENV_ACT | Q9: CAP2ACT | R9: Peak | T9: CALIBRATION | W9: Sets | X9: Region | Y9: TechName | Z9: TechDesc | AA9: Tact | AB9: Tcap | AC9: Tslvl | AD9: PrimaryCG | AE9: Vintage
B10: *Technology Name | C10: Input Commodity | D10: Output Commodity | E10: Existing Installed Capacity | F10: Existing Installed Capacity | G10: Retirement Capacity | H10: Retirement Capacity | I10: Efficiency | J10: Utilisation Factor | K10: Invesctment Cost | L10: Fixed O&M Cost | M10: Variable O&M Cost | N10: Lifetime | P10: Activity Emission Coefficient | Q10: Capacity to Activity Factor | R10: % contribution to PEAK | T10: Total Production | W10: *Process Set Membership | X10: Region Name | Y10: Technology Name | Z10: Technology Description | AA10: Activity Unit | AB10: Capacity Unit | AC10: TimeSlice level of Process Activity | AD10: Primary Commodity Group | AE10: Vintage Tracking
B11: *Units | E11: =$F$2 -> GW | F11: =$F$2 -> GW | G11: =$F$2 -> GW | H11: =$F$2 -> GW | K11: =$G$2&"/"&$F$2 -> M€2005/GW | L11: =$G$2&"/"&F2 -> M€2005/GW | M11: =$G$2&"/"&$E$2 -> M€2005/PJ | N11: Years | P11: =EnergyBalance!$S$2 -> kt | Q11: =$E$2&"/"&$F$2 -> PJ/GW | T11: REG1 | U11: REG2 | W11: *
B12: =Y12 -> ELCTECOA00 | C12: =$B$2&RIGHT(Sector_Fuels!$L$7,3) -> ELCCOA | D12: =$Y$5 -> ELC | E12: =(-'EB1'!$D$11*$I$12)/($J$12*$Q$12) -> 137.49657 | F12: =(-'EB2'!$D$11*$I$12)/($J$12*$Q$12) -> 0 | I12: 0.384 | J12: 0.85 | L12: 40 | M12: 0.5 | N12: 30 | Q12: 31.536 | R12: 1 | T12: =E12*$J12*$Q12 -> 3685.6781 | U12: =F12*$J12*$Q12 -> 0 | W12: ELE | Y12: =$B$2&$C$5&$I$2&RIGHT(Sector_Fuels!$L$7,3)&"00" -> ELCTECOA00 | Z12: =$D$2&" "&$I$1&RIGHT(Y12,2)&" - "&EnergyBalance!D3 -> Power Plants Existing00 - Solid Fuels | AA12: =$E$2 -> PJ | AB12: =$F$2 -> GW | AC12: SEASON
D13: =$Y$6 -> ELCCO2 | P13: =99.8/I12 -> 259.89583 | Y13: =$B$2&$C$5&$I$2&RIGHT(Sector_Fuels!$L$8,3)&"00" -> ELCTEGAS00 | Z13: =$D$2&" "&$I$1&RIGHT(Y13,2)&" - "&EnergyBalance!E3 -> Power Plants Existing00 - Natural Gas | AA13: =$E$2 -> PJ | AB13: =$F$2 -> GW
B14: =Y13 -> ELCTEGAS00 | C14: =$B$2&RIGHT(Sector_Fuels!$L$8,3) -> ELCGAS | D14: =$Y$5 -> ELC | E14: =(-'EB1'!$E$11*$I$14)/($J$14*$Q$14) -> 0 | F14: =(-'EB2'!$E$11*$I$14)/($J$14*$Q$14) -> 103.62609 | I14: 0.4929 | J14: 0.85 | L14: 35 | M14: 0.4 | N14: 20 | Q14: 31.536 | R14: 1 | T14: =E14*J14*Q14 -> 0 | U14: =F14*$J14*$Q14 -> 2777.7596 | Y14: =$B$2&$C$5&$I$2&RIGHT(Sector_Fuels!$L$9,3)&"00" -> ELCTEOIL00 | Z14: =$D$2&" "&$I$1&RIGHT(Y14,2)&" - "&EnergyBalance!F3 -> Power Plants Existing00 - Crude Oil | AA14: =$E$2 -> PJ | AB14: =$F$2 -> GW
D15: =$Y$6 -> ELCCO2 | P15: =56.1/I14 -> 113.81619 | Y15: =$B$2&$E$5&$I$2&RIGHT(Sector_Fuels!$L$10,3)&"00" -> ELCRERNW00 | Z15: =$D$2&" "&$I$1&RIGHT(Y15,2)&" - "&EnergyBalance!H3 -> Power Plants Existing00 - Renewable Energies | AA15: =$E$2 -> PJ | AB15: =$F$2 -> GW
B16: =Y14 -> ELCTEOIL00 | C16: =$B$2&RIGHT(Sector_Fuels!$L$9,3) -> ELCOIL | D16: =$Y$5 -> ELC | E16: =((-'EB1'!$F$11*$I$16)/($J$16*$Q$16)) -> 3.4263615 | F16: =((-'EB2'!$F$11*$I$16)/($J$16*$Q$16)) -> 7.9948434 | I16: 0.25 | J16: 0.85 | L16: 20 | M16: 0.2 | N16: 30 | Q16: 31.536 | R16: 1 | T16: =E16*J16*Q16 -> 91.845675 | U16: =F16*$J16*$Q16 -> 214.30658 | Y16: =$B$2&$C$5&$I$2&RIGHT(Sector_Fuels!$L$11,3)&"00" -> ELCTENUC00 | Z16: =$D$2&" "&$I$1&RIGHT(Y16,2)&" - "&EnergyBalance!G3 -> Power Plants Existing00 - Nuclear Energy | AA16: =$E$2 -> PJ | AB16: =$F$2 -> GW | AC16: SEASON
D17: =$Y$6 -> ELCCO2 | P17: =76.4/I16 -> 305.6 | Y17: =$B$2&$C$5&$J$2&RIGHT(Sector_Fuels!$L$7,3)&"00" -> ELCTNCOA00 | Z17: =$D$2&" "&$J$1&RIGHT(Y17,2)&" - "&EnergyBalance!D3 -> Power Plants New00 - Solid Fuels | AA17: =$E$2 -> PJ | AB17: =$F$2 -> GW | AC17: SEASON
B18: =Y15 -> ELCRERNW00 | C18: =$B$2&RIGHT(Sector_Fuels!$L$10,3) -> ELCRNW | D18: =$Y$5 -> ELC | E18: =(-'EB1'!$H$11*$I$18)/($J$18*$Q$18) -> 88.483849 | F18: =(-'EB2'!$H$11*$I$18)/($J$18*$Q$18) -> 0 | G18: =E18 -> 88.483849 | H18: =F18 -> 0 | I18: 1 | J18: 0.45 | L18: 70 | Q18: 31.536 | R18: 0.5 | T18: =E18*J18*Q18 -> 1255.692 | U18: =F18*$J18*$Q18 -> 0 | Y18: =$B$2&$C$5&$J$2&RIGHT(Sector_Fuels!$L$8,3)&"00" -> ELCTNGAS00 | Z18: =$D$2&" "&$J$1&RIGHT(Y18,2)&" - "&EnergyBalance!E3 -> Power Plants New00 - Natural Gas | AA18: =$E$2 -> PJ | AB18: =$F$2 -> GW
B19: =Y16 -> ELCTENUC00 | C19: =$B$2&RIGHT(Sector_Fuels!$L$11,3) -> ELCNUC | D19: =$Y$5 -> ELC | E19: =(-'EB1'!$G$11*$I$19)/($J$19*$Q$19) -> 0 | F19: =(-'EB2'!$G$11*$I$19)/($J$19*$Q$19) -> 125.28184 | G19: =E19 -> 0 | H19: =F19 -> 125.28184 | I19: 0.33 | J19: 0.9 | L19: 38 | M19: 0.27 | Q19: 31.536 | R19: 1 | T19: =E19*J19*Q19 -> 0 | U19: =F19*$J19*$Q19 -> 3555.7992 | Y19: =$B$2&$C$5&$J$2&RIGHT(Sector_Fuels!$L$9,3)&"00" -> ELCTNOIL00 | Z19: =$D$2&" "&$J$1&RIGHT(Y19,2)&" - "&EnergyBalance!F3 -> Power Plants New00 - Crude Oil | AA19: =$E$2 -> PJ | AB19: =$F$2 -> GW
B20: =Y17 -> ELCTNCOA00 | C20: =$B$2&RIGHT(Sector_Fuels!$L$7,3) -> ELCCOA | D20: =$Y$5 -> ELC | I20: 0.42 | J20: 0.85 | K20: 1650 | L20: 35 | M20: 0.4 | N20: 40 | O20: 2006 | Q20: 31.536 | R20: 1
D21: =$Y$6 -> ELCCO2 | P21: =99.8/I20 -> 237.61905
B22: =Y18 -> ELCTNGAS00 | C22: =$B$2&RIGHT(Sector_Fuels!$L$8,3) -> ELCGAS | D22: =$Y$5 -> ELC | I22: 0.52 | J22: 0.85 | K22: 750 | L22: 30 | M22: 0.35 | N22: 30 | O22: 2006 | Q22: 31.536 | R22: 1
D23: =$Y$6 -> ELCCO2 | P23: =56.1/I22 -> 107.88462
B24: =Y19 -> ELCTNOIL00 | C24: =$B$2&RIGHT(Sector_Fuels!$L$9,3) -> ELCOIL | D24: =$Y$5 -> ELC | I24: 0.3 | J24: 0.85 | K24: 250 | L24: 15 | M24: 0.2 | N24: 40 | O24: 2005 | Q24: 31.536 | R24: 1
D25: =$Y$6 -> ELCCO2 | P25: =76.4/I24 -> 254.66667
C31: User inputs
C32: Linked to the Energy Balance

Sheet DemTechs_TPS
B1: Sector Name | C1: Description | D1: Type | E1: Default Unit | F1: Currency Unit | H1: Existing
B2: =EnergyBalance!B8 -> TPS | C2: =EnergyBalance!C8 -> Total Primary Supply | D2: ="Demand Technology" -> Demand Technology | E2: =EnergyBalance!R2 -> PJ | F2: =EnergyBalance!Q2 -> M€2005 | H2: E | M2: ~FI_Comm
M3: Csets | N3: Region | O3: CommName | P3: CommDesc | Q3: Unit | R3: LimType | S3: CTSLvl | T3: PeakTS | U3: Ctype
M4: *Commodity Set Membership | N4: Region Name | O4: Commodity Name | P4: Commodity Description | Q4: Unit | R4: Sense of the Balance EQN. | S4: Timeslice Level | T4: Peak Monitoring | U4: Electricity Indicator
M5: DEM | O5: =B2&EnergyBalance!D2 -> TPSCOA | P5: =LEFT($D$2,6)&" "&$C$2&" - "&EnergyBalance!D2 -> Demand Total Primary Supply - COA | Q5: =$E$2 -> PJ
D8: ~FI_T | M8: ~FI_Process
B9: TechName | C9: Comm-IN | D9: Comm-OUT | E9: STOCK~REG1 | F9: STOCK~REG2 | G9: EFF | H9: AFA | I9: INVCOST | J9: FIXOM | K9: LIFE | M9: Sets | N9: Region | O9: TechName | P9: TechDesc | Q9: Tact | R9: Tcap | S9: Tslvl | T9: PrimaryCG | U9: Vintage
B10: *Technology Name | C10: Input Commodity | D10: Output Commodity | E10: Existing Installed Capacity | F10: Existing Installed Capacity | G10: Efficiency | H10: Utilisation Factor | I10: Invesctment Cost | J10: Fixed O&M Cost | K10: Lifetime | M10: *Process Set Membership | N10: Region Name | O10: Technology Name | P10: Technology Description | Q10: Activity Unit | R10: Capacity Unit | S10: TimeSlice level of Process Activity | T10: Primary Commodity Group | U10: Vintage Tracking
B11: *Units | E11: =$E$2&"a" -> PJa | F11: =$E$2&"a" -> PJa | I11: =$F$2&"/"&$E$2 -> M€2005/PJ | J11: =$F$2&"/"&$E$2&"a" -> M€2005/PJa | K11: Years | M11: *
B12: =O12 -> DTPSCOA | C12: =RIGHT(B12,3) -> COA | D12: =$O$5 -> TPSCOA | G12: 1 | H12: 0.95 | I12: 10 | J12: =I12*0.02 -> 0.2 | K12: 20 | M12: DMD | O12: =LEFT(M12,1)&B2&RIGHT(P12,3) -> DTPSCOA | P12: =$D$2&" "&$C$2&" - "&EnergyBalance!D2 -> Demand Technology Total Primary Supply - COA | Q12: =$E$2 -> PJ | R12: =$E$2&"a" -> PJa
C23: User inputs
C24: Linked to the Energy Balance

Sheet DemTechs_ELC
B1: Sector Name | C1: Description | D1: Type | E1: Default Unit | F1: Currency Unit | H1: Existing
B2: =EnergyBalance!B8 -> TPS | C2: =EnergyBalance!C8 -> Total Primary Supply | D2: ="Demand Technology" -> Demand Technology | E2: =EnergyBalance!R2 -> PJ | F2: =EnergyBalance!Q2 -> M€2005 | H2: E | M2: ~FI_Comm
M3: Csets | N3: Region | O3: CommName | P3: CommDesc | Q3: Unit | R3: LimType | S3: CTSLvl | T3: PeakTS | U3: Ctype
M4: *Commodity Set Membership | N4: Region Name | O4: Commodity Name | P4: Commodity Description | Q4: Unit | R4: Sense of the Balance EQN. | S4: Timeslice Level | T4: Peak Monitoring | U4: Electricity Indicator
M5: DEM | O5: =B2&EnergyBalance!K2 -> TPSELC | P5: =LEFT($D$2,6)&" "&$C$2&" - "&EnergyBalance!K2 -> Demand Total Primary Supply - ELC | Q5: =$E$2 -> PJ
D8: ~FI_T | M8: ~FI_Process
B9: TechName | C9: Comm-IN | D9: Comm-OUT | E9: STOCK~REG1 | F9: STOCK~REG2 | G9: EFF | H9: AFA | I9: INVCOST | J9: FIXOM | K9: LIFE | M9: Sets | N9: Region | O9: TechName | P9: TechDesc | Q9: Tact | R9: Tcap | S9: Tslvl | T9: PrimaryCG | U9: Vintage
B10: *Technology Name | C10: Input Commodity | D10: Output Commodity | E10: Existing Installed Capacity | F10: Existing Installed Capacity | G10: Efficiency | H10: Utilisation Factor | I10: Invesctment Cost | J10: Fixed O&M Cost | K10: Lifetime | M10: *Process Set Membership | N10: Region Name | O10: Technology Name | P10: Technology Description | Q10: Activity Unit | R10: Capacity Unit | S10: TimeSlice level of Process Activity | T10: Primary Commodity Group | U10: Vintage Tracking
B11: *Units | E11: =$E$2&"a" -> PJa | F11: =$E$2&"a" -> PJa | I11: =$F$2&"/"&$E$2 -> M€2005/PJ | J11: =$F$2&"/"&$E$2&"a" -> M€2005/PJa | K11: Years | M11: *
B12: =O12 -> DTPSELC | C12: =RIGHT(B12,3) -> ELC | D12: =$O$5 -> TPSELC | G12: 1 | H12: 0.95 | I12: 10 | J12: =I12*0.02 -> 0.2 | K12: 20 | M12: DMD | O12: =LEFT(M12,1)&B2&RIGHT(P12,3) -> DTPSELC | P12: =$D$2&" "&$C$2&" - "&EnergyBalance!K2 -> Demand Technology Total Primary Supply - ELC | Q12: =$E$2 -> PJ | R12: =$E$2&"a" -> PJa
C23: User inputs
C24: Linked to the Energy Balance

Sheet DemTechs_RSD
B1: Sector Name | C1: Description | D1: Type | E1: Default Unit | F1: Currency Unit | H1: Existing | I1: New
B2: =EnergyBalance!B16 -> RSD | C2: =EnergyBalance!C16 -> Residential | D2: ="Demand Technologies" -> Demand Technologies | E2: =EnergyBalance!R2 -> PJ | F2: =EnergyBalance!Q2 -> M€2005 | H2: E | I2: N | O2: ~FI_Comm
O3: Csets | P3: Region | Q3: CommName | R3: CommDesc | S3: Unit | T3: LimType | U3: CTSLvl | V3: PeakTS | W3: Ctype
O4: *Commodity Set Membership | P4: Region Name | Q4: Commodity Name | R4: Commodity Description | S4: Unit | T4: Sense of the Balance EQN. | U4: Timeslice Level | V4: Peak Monitoring | W4: Electricity Indicator
O5: DEM | Q5: =LEFT($O$5,1)&LEFT(B2,1)&EnergyBalance!$C$44 -> DROT | R5: =LEFT($D$2,6)&" "&$C$2& " Sector - "&EnergyBalance!$N$44 -> Demand Residential Sector - Other | S5: =$E$2 -> PJ
O6: ENV | Q6: =$B$2&EnergyBalance!$C$52 -> RSDCO2 | R6: =$C$2&" "&EnergyBalance!$C$53 -> Residential Carbon dioxide | S6: =EnergyBalance!$S$2 -> kt
D8: ~FI_T | O8: ~FI_Process
B9: TechName | C9: Comm-IN | D9: Comm-OUT | E9: STOCK~REG1 | F9: STOCK~REG2 | G9: EFF | H9: AFA | I9: INVCOST | J9: FIXOM | K9: LIFE | L9: START | M9: ENV_ACT | O9: Sets | P9: Region | Q9: TechName | R9: TechDesc | S9: Tact | T9: Tcap | U9: Tslvl | V9: PrimaryCG | W9: Vintage
B10: *Technology Name | C10: Input Commodity | D10: Output Commodity | E10: Existing Installed Capacity | F10: Existing Installed Capacity | G10: Efficiency | H10: Utilisation Factor | I10: Invesctment Cost | J10: Fixed O&M Cost | K10: Lifetime | M10: Activity Emission Coefficient | O10: *Process Set Membership | P10: Region Name | Q10: Technology Name | R10: Technology Description | S10: Activity Unit | T10: Capacity Unit | U10: TimeSlice level of Process Activity | V10: Primary Commodity Group | W10: Vintage Tracking
B11: *Units | E11: =E2&"a" -> PJa | F11: =E2&"a" -> PJa | I11: =$F$2&"/"&$E$2 -> M€2005/PJ | J11: =$F$2&"/"&$E$2&"a" -> M€2005/PJa | K11: Years | M11: =EnergyBalance!$S$2 -> kt | O11: *
B12: =Q12 -> ROTEGAS | C12: =$B$2&RIGHT(B12,3) -> RSDGAS | D12: =$Q$5 -> DROT | E12: ='EB1'!$E$16/$H$12*1.01 -> 0 | F12: ='EB2'!$E$16/$H$12*1.01 -> 5485.6747 | G12: 1 | H12: 0.95 | J12: =I12*0.02 -> 0 | K12: 20 | O12: DMD | Q12: =LEFT(EnergyBalance!$B$16)&EnergyBalance!$C$44&$H$2&EnergyBalance!E2 -> ROTEGAS | R12: =$D$2&" "&$C$2& " Sector - "&" "&$H$1&" "&EnergyBalance!$N$44&" - "&EnergyBalance!$E$3 -> Demand Technologies Residential Sector - Existing Other - Natural Gas | S12: =$E$2 -> PJ | T12: =$E$2&"a" -> PJa
D13: =$Q$6 -> RSDCO2 | M13: =56.1/G12 -> 56.1 | Q13: =LEFT(EnergyBalance!$B$16)&EnergyBalance!$C$44&$I$2&EnergyBalance!E2 -> ROTNGAS | R13: =$D$2&" "&$C$2& " Sector - "&" "&$I$1&" "&EnergyBalance!$N$44&" - "&EnergyBalance!$E$3 -> Demand Technologies Residential Sector - New Other - Natural Gas | S13: =$E$2 -> PJ | T13: =$E$2&"a" -> PJa
B14: =Q13 -> ROTNGAS | C14: =$B$2&RIGHT(B14,3) -> RSDGAS | D14: =$Q$5 -> DROT | G14: 1.2 | H14: 0.95 | I14: 12 | J14: =I14*0.02 -> 0.24 | K14: 20 | L14: 2006
D15: =$Q$6 -> RSDCO2 | M15: =56.1/G14 -> 46.75
C23: User inputs
C24: Linked to the Energy Balance

Sheet DemTechs_TRA
B1: Sector Name | C1: Description | D1: Type | E1: Default Unit | F1: Currency Unit | G1: Capacity | H1: Existing | I1: New
B2: =EnergyBalance!B20 -> TRA | C2: =EnergyBalance!C20 -> Transport | D2: Demand Technologies | E2: =EnergyBalance!R2 -> PJ | F2: =EnergyBalance!Q2 -> M€2005 | G2: 000_Units | H2: E | I2: N | O2: ~FI_Comm
O3: Csets | P3: Region | Q3: CommName | R3: CommDesc | S3: Unit | T3: LimType | U3: CTSLvl | V3: PeakTS | W3: Ctype
O4: *Commodity Set Membership | P4: Region Name | Q4: Commodity Name | R4: Commodity Description | S4: Unit | T4: Sense of the Balance EQN. | U4: Timeslice Level | V4: Peak Monitoring | W4: Electricity Indicator
O5: DEM | Q5: =LEFT($O$5,1)&LEFT($B$2,1)&EnergyBalance!$C$49 -> DTD1 | R5: =LEFT($D$2,6)&" "&$C$2& " Sector - "&EnergyBalance!$N$49 -> Demand Transport Sector - Demand 1 | S5: =$E$2 -> PJ
O6: ENV | Q6: =$B$2&EnergyBalance!$C$52 -> TRACO2 | R6: =$C$2&" "&EnergyBalance!$C$53 -> Transport Carbon dioxide | S6: =EnergyBalance!$S$2 -> kt
D8: ~FI_T | O8: ~FI_Process
B9: TechName | C9: Comm-IN | D9: Comm-OUT | E9: STOCK~REG1 | F9: STOCK~REG2 | G9: EFF | H9: AFA | I9: INVCOST | J9: FIXOM | K9: LIFE | L9: START | M9: ENV_ACT | O9: Sets | P9: Region | Q9: TechName | R9: TechDesc | S9: Tact | T9: Tcap | U9: Tslvl | V9: PrimaryCG | W9: Vintage
B10: *Technology Name | C10: Input Commodity | D10: Output Commodity | E10: Existing Installed Capacity | F10: Existing Installed Capacity | G10: Efficiency | H10: Utilisation Factor | I10: Invesctment Cost | J10: Fixed O&M Cost | K10: Lifetime | M10: Activity Emission Coefficient | O10: *Process Set Membership | P10: Region Name | Q10: Technology Name | R10: Technology Description | S10: Activity Unit | T10: Capacity Unit | U10: TimeSlice level of Process Activity | V10: Primary Commodity Group | W10: Vintage Tracking
B11: *Units | E11: =E2&"a" -> PJa | F11: =E2&"a" -> PJa | I11: =$F$2&"/"&$E$2 -> M€2005/PJ | J11: =$F$2&"/"&$E$2&"a" -> M€2005/PJa | K11: Years | M11: =EnergyBalance!$S$2 -> kt | O11: DMD | Q11: =LEFT($B$2)&EnergyBalance!$C$44&$H$2&EnergyBalance!F2 -> TOTEOIL | R11: =$D$2&" "&$C$2& " Sector - "&" "&$H$1&" "&EnergyBalance!$N$40&" - "&EnergyBalance!$F$3 -> Demand Technologies Transport Sector - Existing - Crude Oil | S11: =$E$2 -> PJ | T11: =$E$2&"a" -> PJa
B12: =Q11 -> TOTEOIL | C12: =$B$2&RIGHT(B12,3) -> TRAOIL | D12: =$Q$5 -> DTD1 | E12: ='EB1'!$F$20/$H$12*1.01 -> 4999.9205 | F12: ='EB2'!$F$20/$H$12*1.01 -> 11666.481 | G12: 1 | H12: 0.9 | J12: =I12*0.02 -> 0 | K12: 15 | Q12: =LEFT($B$2)&EnergyBalance!$C$44&$I$2&EnergyBalance!F2 -> TOTNOIL | R12: =$D$2&" "&$C$2& " Sector - "&" "&$I$1&" "&EnergyBalance!$N$40&" - "&EnergyBalance!$F$3 -> Demand Technologies Transport Sector - New - Crude Oil | S12: =$E$2 -> PJ | T12: =$E$2&"a" -> PJa
D13: =$Q$6 -> TRACO2 | M13: =65/G12 -> 65
B14: =Q12 -> TOTNOIL | C14: =$B$2&RIGHT(B14,3) -> TRAOIL | D14: =$Q$5 -> DTD1 | G14: 1.1 | H14: 0.9 | I14: 10 | J14: =I14*0.02 -> 0.2 | K14: 15 | L14: 2006
D15: =$Q$6 -> TRACO2 | M15: =65/G14 -> 59.090909
C23: User inputs
C24: Linked to the Energy Balance

Sheet Demands
B1: Sector Name | C1: Commodity | D1: Description | E1: Default Unit | G1: Currency Unit
B2: DEM | E2: =EnergyBalance!R2 -> PJ | G2: =EnergyBalance!Q2 -> M€2005
D5: ~FI_T | Q5: ~FI_T
B6: Region | C6: Attribute | D6: CommName | E6: *Unit | F6: 2005 | G6: 2006 | H6: 2010 | I6: 2015 | J6: 2020 | N6: Region | O6: Attribute | P6: CommName | Q6: Timeslices | R6: 2005
B7: Region Name | C7: * | D7: Demand Commodity Name | E7: Demand Unit | F7: Demand Value | L7: Demand Driver (annual growth) | N7: Region Name | O7: * | P7: Demand Commodity Name
C8: *Units | F8: =E2 -> PJ | O8: *Units
B9: REG1 | C9: Demand | D9: =DemTechs_TPS!O5 -> TPSCOA | E9: PJ | F9: ='EB1'!$D$24 -> 3596.806 | N9: REG1 | O9: COM_FR | P9: =DemTechs_ELC!$O$5 -> TPSELC | Q9: SD | R9: 0.3
B10: REG1 | C10: Demand | D10: =DemTechs_RSD!$Q$5 -> DROT | E10: PJ | F10: ='EB1'!$E$16 -> 0 | N10: REG1 | O10: COM_FR | P10: =DemTechs_ELC!$O$5 -> TPSELC | Q10: SN | R10: 0.2
B11: REG1 | C11: Demand | D11: =DemTechs_TRA!$Q$5 -> DTD1 | E11: PJ | F11: ='EB1'!$F$20 -> 4455.3747 | N11: REG1 | O11: COM_FR | P11: =DemTechs_ELC!$O$5 -> TPSELC | Q11: WD | R11: 0.27
